[2023-10-29T16:33:36.240+0000] {taskinstance.py:1159} INFO - Dependencies all met for dep_context=non-requeueable deps ti=<TaskInstance: our_dag_with_python_operator_v1.first_task scheduled__2023-10-13T00:00:00+00:00 [queued]>
[2023-10-29T16:33:36.260+0000] {taskinstance.py:1159} INFO - Dependencies all met for dep_context=requeueable deps ti=<TaskInstance: our_dag_with_python_operator_v1.first_task scheduled__2023-10-13T00:00:00+00:00 [queued]>
[2023-10-29T16:33:36.261+0000] {taskinstance.py:1361} INFO - Starting attempt 1 of 6
[2023-10-29T16:33:36.276+0000] {taskinstance.py:1382} INFO - Executing <Task(PythonOperator): first_task> on 2023-10-13 00:00:00+00:00
[2023-10-29T16:33:36.282+0000] {standard_task_runner.py:57} INFO - Started process 11076 to run task
[2023-10-29T16:33:36.288+0000] {standard_task_runner.py:84} INFO - Running: ['***', 'tasks', 'run', 'our_dag_with_python_operator_v1', 'first_task', 'scheduled__2023-10-13T00:00:00+00:00', '--job-id', '3313', '--raw', '--subdir', 'DAGS_FOLDER/create_dag_with_python_operator.py', '--cfg-path', '/tmp/tmpawn_xxd3']
[2023-10-29T16:33:36.293+0000] {standard_task_runner.py:85} INFO - Job 3313: Subtask first_task
[2023-10-29T16:33:36.399+0000] {task_command.py:416} INFO - Running <TaskInstance: our_dag_with_python_operator_v1.first_task scheduled__2023-10-13T00:00:00+00:00 [running]> on host 9bb87dc64328
[2023-10-29T16:33:36.636+0000] {local_task_job_runner.py:115} ERROR - Received SIGTERM. Terminating subprocesses
[2023-10-29T16:33:36.850+0000] {process_utils.py:131} INFO - Sending 15 to group 11076. PIDs of all processes in the group: [11076]
[2023-10-29T16:33:36.912+0000] {process_utils.py:86} INFO - Sending the signal 15 to group 11076
[2023-10-29T16:33:36.935+0000] {taskinstance.py:1632} ERROR - Received SIGTERM. Terminating subprocesses.
[2023-10-29T16:33:37.012+0000] {taskinstance.py:1937} ERROR - Task failed with exception
Traceback (most recent call last):
  File "/home/airflow/.local/lib/python3.8/site-packages/airflow/models/taskinstance.py", line 1518, in _run_raw_task
    self._execute_task_with_callbacks(context, test_mode, session=session)
  File "/home/airflow/.local/lib/python3.8/site-packages/airflow/models/taskinstance.py", line 1662, in _execute_task_with_callbacks
    self.log.info(
  File "/usr/local/lib/python3.8/logging/__init__.py", line 1446, in info
    self._log(INFO, msg, args, **kwargs)
  File "/usr/local/lib/python3.8/logging/__init__.py", line 1587, in _log
    record = self.makeRecord(self.name, level, fn, lno, msg, args,
  File "/usr/local/lib/python3.8/logging/__init__.py", line 1556, in makeRecord
    rv = _logRecordFactory(name, level, fn, lno, msg, args, exc_info, func,
  File "/usr/local/lib/python3.8/logging/__init__.py", line 314, in __init__
    if (args and len(args) == 1 and isinstance(args[0], collections.abc.Mapping)
  File "/usr/local/lib/python3.8/abc.py", line 98, in __instancecheck__
    return _abc_instancecheck(cls, instance)
  File "/home/airflow/.local/lib/python3.8/site-packages/airflow/models/taskinstance.py", line 1634, in signal_handler
    raise AirflowException("Task received SIGTERM signal")
airflow.exceptions.AirflowException: Task received SIGTERM signal
[2023-10-29T16:33:37.157+0000] {taskinstance.py:1400} INFO - Marking task as UP_FOR_RETRY. dag_id=our_dag_with_python_operator_v1, task_id=first_task, execution_date=20231013T000000, start_date=20231029T163336, end_date=20231029T163337
[2023-10-29T16:33:37.384+0000] {standard_task_runner.py:104} ERROR - Failed to execute job 3313 for task first_task (Task received SIGTERM signal; 11076)
[2023-10-29T16:33:37.688+0000] {process_utils.py:79} INFO - Process psutil.Process(pid=11076, status='terminated', exitcode=1, started='16:33:35') (11076) terminated with exit code 1
[2023-10-29T16:33:37.700+0000] {local_task_job_runner.py:228} INFO - Task exited with return code 143
[2023-10-29T16:33:37.915+0000] {taskinstance.py:2778} INFO - 0 downstream tasks scheduled from follow-on schedule check
[2023-10-29T16:33:41.648+0000] {local_task_job_runner.py:115} ERROR - Received SIGTERM. Terminating subprocesses
[2023-10-29T16:33:41.703+0000] {local_task_job_runner.py:228} INFO - Task exited with return code 143
[2023-10-29T16:33:41.941+0000] {taskinstance.py:2778} INFO - 0 downstream tasks scheduled from follow-on schedule check
