[2023-10-30T15:04:30.300+0000] {taskinstance.py:1159} INFO - Dependencies all met for dep_context=non-requeueable deps ti=<TaskInstance: our_dag_with_python_operator_v6.first_task manual__2023-10-30T15:04:22.406282+00:00 [queued]>
[2023-10-30T15:04:30.328+0000] {taskinstance.py:1159} INFO - Dependencies all met for dep_context=requeueable deps ti=<TaskInstance: our_dag_with_python_operator_v6.first_task manual__2023-10-30T15:04:22.406282+00:00 [queued]>
[2023-10-30T15:04:30.337+0000] {taskinstance.py:1361} INFO - Starting attempt 1 of 6
[2023-10-30T15:04:30.422+0000] {taskinstance.py:1382} INFO - Executing <Task(PythonOperator): first_task> on 2023-10-30 15:04:22.406282+00:00
[2023-10-30T15:04:30.490+0000] {standard_task_runner.py:57} INFO - Started process 5721 to run task
[2023-10-30T15:04:30.516+0000] {standard_task_runner.py:84} INFO - Running: ['***', 'tasks', 'run', 'our_dag_with_python_operator_v6', 'first_task', 'manual__2023-10-30T15:04:22.406282+00:00', '--job-id', '5282', '--raw', '--subdir', 'DAGS_FOLDER/create_dag_with_python_operator.py', '--cfg-path', '/tmp/tmppyjn77nq']
[2023-10-30T15:04:30.547+0000] {standard_task_runner.py:85} INFO - Job 5282: Subtask first_task
[2023-10-30T15:04:30.739+0000] {task_command.py:416} INFO - Running <TaskInstance: our_dag_with_python_operator_v6.first_task manual__2023-10-30T15:04:22.406282+00:00 [running]> on host 9bb87dc64328
[2023-10-30T15:04:30.906+0000] {taskinstance.py:1662} INFO - Exporting env vars: AIRFLOW_CTX_DAG_OWNER='coder3j' AIRFLOW_CTX_DAG_ID='our_dag_with_python_operator_v6' AIRFLOW_CTX_TASK_ID='first_task' AIRFLOW_CTX_EXECUTION_DATE='2023-10-30T15:04:22.406282+00:00' AIRFLOW_CTX_TRY_NUMBER='1' AIRFLOW_CTX_DAG_RUN_ID='manual__2023-10-30T15:04:22.406282+00:00'
[2023-10-30T15:04:30.970+0000] {taskinstance.py:1937} ERROR - Task failed with exception
Traceback (most recent call last):
  File "/home/airflow/.local/lib/python3.8/site-packages/airflow/operators/python.py", line 192, in execute
    return_value = self.execute_callable()
  File "/home/airflow/.local/lib/python3.8/site-packages/airflow/operators/python.py", line 209, in execute_callable
    return self.python_callable(*self.op_args, **self.op_kwargs)
  File "/opt/airflow/dags/create_dag_with_python_operator.py", line 14, in greet
    print(f"Hello world! name {name}",
NameError: name 'name' is not defined
[2023-10-30T15:04:31.002+0000] {taskinstance.py:1400} INFO - Marking task as UP_FOR_RETRY. dag_id=our_dag_with_python_operator_v6, task_id=first_task, execution_date=20231030T150422, start_date=20231030T150430, end_date=20231030T150431
[2023-10-30T15:04:31.020+0000] {standard_task_runner.py:104} ERROR - Failed to execute job 5282 for task first_task (name 'name' is not defined; 5721)
[2023-10-30T15:04:31.094+0000] {local_task_job_runner.py:228} INFO - Task exited with return code 1
[2023-10-30T15:04:31.123+0000] {taskinstance.py:2778} INFO - 0 downstream tasks scheduled from follow-on schedule check
