[2023-10-30T14:17:28.480+0000] {taskinstance.py:1159} INFO - Dependencies all met for dep_context=non-requeueable deps ti=<TaskInstance: our_dag_with_python_operator_v4.first_task scheduled__2021-10-08T00:00:00+00:00 [queued]>
[2023-10-30T14:17:28.565+0000] {taskinstance.py:1159} INFO - Dependencies all met for dep_context=requeueable deps ti=<TaskInstance: our_dag_with_python_operator_v4.first_task scheduled__2021-10-08T00:00:00+00:00 [queued]>
[2023-10-30T14:17:28.571+0000] {taskinstance.py:1361} INFO - Starting attempt 1 of 6
[2023-10-30T14:17:28.638+0000] {taskinstance.py:1382} INFO - Executing <Task(PythonOperator): first_task> on 2021-10-08 00:00:00+00:00
[2023-10-30T14:17:28.684+0000] {standard_task_runner.py:57} INFO - Started process 881 to run task
[2023-10-30T14:17:28.745+0000] {standard_task_runner.py:84} INFO - Running: ['***', 'tasks', 'run', 'our_dag_with_python_operator_v4', 'first_task', 'scheduled__2021-10-08T00:00:00+00:00', '--job-id', '3708', '--raw', '--subdir', 'DAGS_FOLDER/create_dag_with_python_operator.py', '--cfg-path', '/tmp/tmpv6459n5j']
[2023-10-30T14:17:28.764+0000] {standard_task_runner.py:85} INFO - Job 3708: Subtask first_task
[2023-10-30T14:17:29.113+0000] {task_command.py:416} INFO - Running <TaskInstance: our_dag_with_python_operator_v4.first_task scheduled__2021-10-08T00:00:00+00:00 [running]> on host 9bb87dc64328
[2023-10-30T14:17:29.454+0000] {taskinstance.py:1662} INFO - Exporting env vars: AIRFLOW_CTX_DAG_OWNER='coder3j' AIRFLOW_CTX_DAG_ID='our_dag_with_python_operator_v4' AIRFLOW_CTX_TASK_ID='first_task' AIRFLOW_CTX_EXECUTION_DATE='2021-10-08T00:00:00+00:00' AIRFLOW_CTX_TRY_NUMBER='1' AIRFLOW_CTX_DAG_RUN_ID='scheduled__2021-10-08T00:00:00+00:00'
[2023-10-30T14:17:29.492+0000] {taskinstance.py:1937} ERROR - Task failed with exception
Traceback (most recent call last):
  File "/home/airflow/.local/lib/python3.8/site-packages/airflow/operators/python.py", line 192, in execute
    return_value = self.execute_callable()
  File "/home/airflow/.local/lib/python3.8/site-packages/airflow/operators/python.py", line 209, in execute_callable
    return self.python_callable(*self.op_args, **self.op_kwargs)
  File "/opt/airflow/dags/create_dag_with_python_operator.py", line 12, in greet
    name = ti.xcoms_pull(task_ids='get_name')
AttributeError: 'TaskInstance' object has no attribute 'xcoms_pull'
[2023-10-30T14:17:29.514+0000] {taskinstance.py:1400} INFO - Marking task as UP_FOR_RETRY. dag_id=our_dag_with_python_operator_v4, task_id=first_task, execution_date=20211008T000000, start_date=20231030T141728, end_date=20231030T141729
[2023-10-30T14:17:29.564+0000] {standard_task_runner.py:104} ERROR - Failed to execute job 3708 for task first_task ('TaskInstance' object has no attribute 'xcoms_pull'; 881)
[2023-10-30T14:17:29.727+0000] {local_task_job_runner.py:228} INFO - Task exited with return code 1
[2023-10-30T14:17:30.008+0000] {taskinstance.py:2778} INFO - 0 downstream tasks scheduled from follow-on schedule check
