[2023-10-30T14:17:32.377+0000] {taskinstance.py:1159} INFO - Dependencies all met for dep_context=non-requeueable deps ti=<TaskInstance: our_dag_with_python_operator_v4.first_task scheduled__2021-10-15T00:00:00+00:00 [queued]>
[2023-10-30T14:17:32.403+0000] {taskinstance.py:1159} INFO - Dependencies all met for dep_context=requeueable deps ti=<TaskInstance: our_dag_with_python_operator_v4.first_task scheduled__2021-10-15T00:00:00+00:00 [queued]>
[2023-10-30T14:17:32.405+0000] {taskinstance.py:1361} INFO - Starting attempt 1 of 6
[2023-10-30T14:17:32.440+0000] {taskinstance.py:1382} INFO - Executing <Task(PythonOperator): first_task> on 2021-10-15 00:00:00+00:00
[2023-10-30T14:17:32.445+0000] {standard_task_runner.py:57} INFO - Started process 896 to run task
[2023-10-30T14:17:32.461+0000] {standard_task_runner.py:84} INFO - Running: ['***', 'tasks', 'run', 'our_dag_with_python_operator_v4', 'first_task', 'scheduled__2021-10-15T00:00:00+00:00', '--job-id', '3718', '--raw', '--subdir', 'DAGS_FOLDER/create_dag_with_python_operator.py', '--cfg-path', '/tmp/tmpn69zmjwm']
[2023-10-30T14:17:32.471+0000] {standard_task_runner.py:85} INFO - Job 3718: Subtask first_task
[2023-10-30T14:17:32.575+0000] {task_command.py:416} INFO - Running <TaskInstance: our_dag_with_python_operator_v4.first_task scheduled__2021-10-15T00:00:00+00:00 [running]> on host 9bb87dc64328
[2023-10-30T14:17:32.730+0000] {taskinstance.py:1662} INFO - Exporting env vars: AIRFLOW_CTX_DAG_OWNER='coder3j' AIRFLOW_CTX_DAG_ID='our_dag_with_python_operator_v4' AIRFLOW_CTX_TASK_ID='first_task' AIRFLOW_CTX_EXECUTION_DATE='2021-10-15T00:00:00+00:00' AIRFLOW_CTX_TRY_NUMBER='1' AIRFLOW_CTX_DAG_RUN_ID='scheduled__2021-10-15T00:00:00+00:00'
[2023-10-30T14:17:32.732+0000] {taskinstance.py:1937} ERROR - Task failed with exception
Traceback (most recent call last):
  File "/home/airflow/.local/lib/python3.8/site-packages/airflow/operators/python.py", line 192, in execute
    return_value = self.execute_callable()
  File "/home/airflow/.local/lib/python3.8/site-packages/airflow/operators/python.py", line 209, in execute_callable
    return self.python_callable(*self.op_args, **self.op_kwargs)
  File "/opt/airflow/dags/create_dag_with_python_operator.py", line 12, in greet
    name = ti.xcoms_pull(task_ids='get_name')
AttributeError: 'TaskInstance' object has no attribute 'xcoms_pull'
[2023-10-30T14:17:32.751+0000] {taskinstance.py:1400} INFO - Marking task as UP_FOR_RETRY. dag_id=our_dag_with_python_operator_v4, task_id=first_task, execution_date=20211015T000000, start_date=20231030T141732, end_date=20231030T141732
[2023-10-30T14:17:32.767+0000] {standard_task_runner.py:104} ERROR - Failed to execute job 3718 for task first_task ('TaskInstance' object has no attribute 'xcoms_pull'; 896)
[2023-10-30T14:17:32.799+0000] {local_task_job_runner.py:228} INFO - Task exited with return code 1
[2023-10-30T14:17:32.817+0000] {taskinstance.py:2778} INFO - 0 downstream tasks scheduled from follow-on schedule check
