[2023-10-30T15:11:45.621+0000] {taskinstance.py:1159} INFO - Dependencies all met for dep_context=non-requeueable deps ti=<TaskInstance: our_dag_with_python_operator_v7.first_task scheduled__2022-12-28T00:00:00+00:00 [queued]>
[2023-10-30T15:11:45.628+0000] {taskinstance.py:1159} INFO - Dependencies all met for dep_context=requeueable deps ti=<TaskInstance: our_dag_with_python_operator_v7.first_task scheduled__2022-12-28T00:00:00+00:00 [queued]>
[2023-10-30T15:11:45.628+0000] {taskinstance.py:1361} INFO - Starting attempt 1 of 6
[2023-10-30T15:11:45.637+0000] {taskinstance.py:1382} INFO - Executing <Task(PythonOperator): first_task> on 2022-12-28 00:00:00+00:00
[2023-10-30T15:11:45.643+0000] {standard_task_runner.py:57} INFO - Started process 7898 to run task
[2023-10-30T15:11:45.649+0000] {standard_task_runner.py:84} INFO - Running: ['***', 'tasks', 'run', 'our_dag_with_python_operator_v7', 'first_task', 'scheduled__2022-12-28T00:00:00+00:00', '--job-id', '6186', '--raw', '--subdir', 'DAGS_FOLDER/create_dag_with_python_operator.py', '--cfg-path', '/tmp/tmpsv9h_lxw']
[2023-10-30T15:11:45.652+0000] {standard_task_runner.py:85} INFO - Job 6186: Subtask first_task
[2023-10-30T15:11:45.694+0000] {task_command.py:416} INFO - Running <TaskInstance: our_dag_with_python_operator_v7.first_task scheduled__2022-12-28T00:00:00+00:00 [running]> on host 9bb87dc64328
[2023-10-30T15:11:45.773+0000] {taskinstance.py:1662} INFO - Exporting env vars: AIRFLOW_CTX_DAG_OWNER='coder3j' AIRFLOW_CTX_DAG_ID='our_dag_with_python_operator_v7' AIRFLOW_CTX_TASK_ID='first_task' AIRFLOW_CTX_EXECUTION_DATE='2022-12-28T00:00:00+00:00' AIRFLOW_CTX_TRY_NUMBER='1' AIRFLOW_CTX_DAG_RUN_ID='scheduled__2022-12-28T00:00:00+00:00'
[2023-10-30T15:11:45.784+0000] {taskinstance.py:1937} ERROR - Task failed with exception
Traceback (most recent call last):
  File "/home/airflow/.local/lib/python3.8/site-packages/airflow/operators/python.py", line 192, in execute
    return_value = self.execute_callable()
  File "/home/airflow/.local/lib/python3.8/site-packages/airflow/operators/python.py", line 209, in execute_callable
    return self.python_callable(*self.op_args, **self.op_kwargs)
TypeError: greet() missing 1 required positional argument: 'age'
[2023-10-30T15:11:45.799+0000] {taskinstance.py:1400} INFO - Marking task as UP_FOR_RETRY. dag_id=our_dag_with_python_operator_v7, task_id=first_task, execution_date=20221228T000000, start_date=20231030T151145, end_date=20231030T151145
[2023-10-30T15:11:45.810+0000] {standard_task_runner.py:104} ERROR - Failed to execute job 6186 for task first_task (greet() missing 1 required positional argument: 'age'; 7898)
[2023-10-30T15:11:45.863+0000] {local_task_job_runner.py:228} INFO - Task exited with return code 1
[2023-10-30T15:11:45.878+0000] {taskinstance.py:2778} INFO - 0 downstream tasks scheduled from follow-on schedule check
